Workbook

Sheet Resumo
A1: Registro de Execução dos Testes
A4: Resumo Executivo da Suíte
A5: Métrica | B5: Quantidade | C5: Percentual
A6: Total de Cenários Mapeados | B6: =COUNTA(Execução!$A$2:$A$52) -> 51 | C6: =IF($B$6=0,0,B6/$B$6) -> 1
A7: Cenários Executados | B7: =B6-COUNTIF(Execução!$H$2:$H$52,"Pendente") -> 51 | C7: =IF($B$6=0,0,B7/$B$6) -> 1
A8: Aprovados (Passou) | B8: =COUNTIF(Execução!$H$2:$H$52,"Passou") -> 48 | C8: =IF($B$6=0,0,B8/$B$6) -> 0.94117647
A9: Reprovados (Falhou) | B9: =COUNTIF(Execução!$H$2:$H$52,"Falhou") -> 3 | C9: =IF($B$6=0,0,B9/$B$6) -> 0.058823529
A10: Bloqueados | B10: =COUNTIF(Execução!$H$2:$H$52,"Bloqueado") -> 0 | C10: =IF($B$6=0,0,B10/$B$6) -> 0
A11: Pendentes (não executados) | B11: =COUNTIF(Execução!$H$2:$H$52,"Pendente") -> 0 | C11: =IF($B$6=0,0,B11/$B$6) -> 0
A13: Por Canal (casos UI / API entram nas duas linhas)
A14: Canal | B14: Total | C14: Passou | D14: Falhou | E14: Bloqueado | F14: Pendente
A15: UI | B15: =COUNTIF(Execução!$D$2:$D$52,"*UI*") -> 35 | C15: =COUNTIFS(Execução!$D$2:$D$52,"*UI*",Execução!$H$2:$H$52,"Passou") -> 32 | D15: =COUNTIFS(Execução!$D$2:$D$52,"*UI*",Execução!$H$2:$H$52,"Falhou") -> 3 | E15: =COUNTIFS(Execução!$D$2:$D$52,"*UI*",Execução!$H$2:$H$52,"Bloqueado") -> 0 | F15: =COUNTIFS(Execução!$D$2:$D$52,"*UI*",Execução!$H$2:$H$52,"Pendente") -> 0
A16: API | B16: =COUNTIF(Execução!$D$2:$D$52,"*API*") -> 37 | C16: =COUNTIFS(Execução!$D$2:$D$52,"*API*",Execução!$H$2:$H$52,"Passou") -> 35 | D16: =COUNTIFS(Execução!$D$2:$D$52,"*API*",Execução!$H$2:$H$52,"Falhou") -> 2 | E16: =COUNTIFS(Execução!$D$2:$D$52,"*API*",Execução!$H$2:$H$52,"Bloqueado") -> 0 | F16: =COUNTIFS(Execução!$D$2:$D$52,"*API*",Execução!$H$2:$H$52,"Pendente") -> 0
A18: Por Funcionalidade
A19: Funcionalidade | B19: Total | C19: Passou | D19: Falhou | E19: Bloqueado | F19: Pendente
A20: Cupom | B20: =COUNTIF(Execução!$B$2:$B$52,A20) -> 12 | C20: =COUNTIFS(Execução!$B$2:$B$52,$A20,Execução!$H$2:$H$52,"Passou") -> 11 | D20: =COUNTIFS(Execução!$B$2:$B$52,$A20,Execução!$H$2:$H$52,"Falhou") -> 1 | E20: =COUNTIFS(Execução!$B$2:$B$52,$A20,Execução!$H$2:$H$52,"Bloqueado") -> 0 | F20: =COUNTIFS(Execução!$B$2:$B$52,$A20,Execução!$H$2:$H$52,"Pendente") -> 0
A21: Frete | B21: =COUNTIF(Execução!$B$2:$B$52,A21) -> 7 | C21: =COUNTIFS(Execução!$B$2:$B$52,$A21,Execução!$H$2:$H$52,"Passou") -> 6 | D21: =COUNTIFS(Execução!$B$2:$B$52,$A21,Execução!$H$2:$H$52,"Falhou") -> 1 | E21: =COUNTIFS(Execução!$B$2:$B$52,$A21,Execução!$H$2:$H$52,"Bloqueado") -> 0 | F21: =COUNTIFS(Execução!$B$2:$B$52,$A21,Execução!$H$2:$H$52,"Pendente") -> 0
A22: Carrinho | B22: =COUNTIF(Execução!$B$2:$B$52,A22) -> 9 | C22: =COUNTIFS(Execução!$B$2:$B$52,$A22,Execução!$H$2:$H$52,"Passou") -> 9 | D22: =COUNTIFS(Execução!$B$2:$B$52,$A22,Execução!$H$2:$H$52,"Falhou") -> 0 | E22: =COUNTIFS(Execução!$B$2:$B$52,$A22,Execução!$H$2:$H$52,"Bloqueado") -> 0 | F22: =COUNTIFS(Execução!$B$2:$B$52,$A22,Execução!$H$2:$H$52,"Pendente") -> 0
A23: Pedido | B23: =COUNTIF(Execução!$B$2:$B$52,A23) -> 8 | C23: =COUNTIFS(Execução!$B$2:$B$52,$A23,Execução!$H$2:$H$52,"Passou") -> 7 | D23: =COUNTIFS(Execução!$B$2:$B$52,$A23,Execução!$H$2:$H$52,"Falhou") -> 1 | E23: =COUNTIFS(Execução!$B$2:$B$52,$A23,Execução!$H$2:$H$52,"Bloqueado") -> 0 | F23: =COUNTIFS(Execução!$B$2:$B$52,$A23,Execução!$H$2:$H$52,"Pendente") -> 0
A24: Contrato da API | B24: =COUNTIF(Execução!$B$2:$B$52,A24) -> 15 | C24: =COUNTIFS(Execução!$B$2:$B$52,$A24,Execução!$H$2:$H$52,"Passou") -> 15 | D24: =COUNTIFS(Execução!$B$2:$B$52,$A24,Execução!$H$2:$H$52,"Falhou") -> 0 | E24: =COUNTIFS(Execução!$B$2:$B$52,$A24,Execução!$H$2:$H$52,"Bloqueado") -> 0 | F24: =COUNTIFS(Execução!$B$2:$B$52,$A24,Execução!$H$2:$H$52,"Pendente") -> 0
A25: Total | B25: =SUM(B20:B24) -> 51 | C25: =SUM(C20:C24) -> 48 | D25: =SUM(D20:D24) -> 3 | E25: =SUM(E20:E24) -> 0 | F25: =SUM(F20:F24) -> 0

Sheet Execução
A1: ID | B1: Funcionalidade | C1: Cenário / Descrição | D1: Canal | E1: Referências / Tags | F1: Passos (step by step) | G1: Resultado Esperado | H1: Status | I1: Bug Relacionado | J1: Evidência | K1: Executado por / Data | L1: Observações
A2: CT-01 | B2: Cupom | C2: Aplicar BEMVINDO10 reduz 10% do subtotal dos produtos | D2: UI | E2: CA01, CA09, smoke, automatizar | F2: 1. Acessar a Verzel Store com o carrinho vazio. 2. Adicionar 1 unidade de Calça Jeans Slim e 2 unidades de Boné Aba Curva. 3. Aplicar o cupom BEMVINDO10. 4. Conferir o resumo do carrinho. | G2: Subtotal: R$ 239,70 Desconto: R$ 23,97 Frete: Grátis Total: R$ 215,73 Mensagem do cupom informa que foi aplicado. | H2: Passou | K2: Yasmin Leite / 09-10-2026
A3: CT-02 | B3: Cupom | C3: O desconto do cupom não incide sobre o frete | D3: UI / API | E3: CA01, CA09 | F3: 1. Acessar a Verzel Store com o carrinho vazio. 2. Adicionar 1 unidade de Mochila Urbana 20L. 3. Aplicar o cupom BEMVINDO10. 4. Conferir o resumo do carrinho. 5. Repetir no canal API (Postman): POST /api/carrinho/calcular com os mesmos itens e cupom e conferir os mesmos valores. | G3: Subtotal: R$ 100,00 Desconto: R$ 10,00 Frete: R$ 19,90 Total: R$ 109,90 | H3: Passou | J3: { "itens": [ { "produtoId": "P005", "nome": "Mochila Urbana 20L", "precoUnitario": 100, "quantidade": 1, "total": 100 } ], "subtotal": 100, "desconto": 10, "frete": 19.9, "freteGratis": false, "valorFaltanteFreteGratis": 100, "total": 109.9, "cupom": { "codigo": "BEMVINDO10", "aplicado": true, "mensagem": "Cupom aplicado: 10% de desconto nos produtos." } } | K3: Yasmin Leite / 09-10-2027
A4: CT-03 | B4: Cupom | C4: O código do cupom não diferencia maiúsculas de minúsculas | D4: UI / API | E4: CA02 | F4: 1. Acessar a Verzel Store com o carrinho vazio. 2. Adicionar 1 unidade de Mochila Urbana 20L. 3. Aplicar, um por vez (removendo o cupom entre as tentativas): bemvindo10, BemVindo10, bEmViNdO10. 4. Conferir desconto e total em cada tentativa. 5. Repetir no canal API (Postman): POST /api/carrinho/calcular com os mesmos itens e cupom e conferir os mesmos valores. | G4: Para os três códigos: desconto R$ 10,00 e total R$ 109,90. | H4: Passou | K4: Yasmin Leite / 09-10-2028
A5: CT-04 | B5: Cupom | C5: Espaços no início e no fim do código são ignorados | D5: UI / API | E5: CA02 | F5: 1. Acessar a Verzel Store com o carrinho vazio. 2. Adicionar 1 unidade de Mochila Urbana 20L. 3. Aplicar, um por vez: ' BEMVINDO10' (2 espaços antes), 'BEMVINDO10 ' (2 espaços depois), ' bemvindo10 ' (2 espaços em cada ponta). 4. Conferir desconto e total em cada tentativa. 5. Repetir no canal API (Postman): POST /api/carrinho/calcular com os mesmos itens e cupom e conferir os mesmos valores. | G5: Para os três códigos: desconto R$ 10,00 e total R$ 109,90. | H5: Passou | K5: Yasmin Leite / 09-10-2029
A6: CT-05 | B6: Cupom | C6: Cupom inexistente exibe "Cupom inválido." e não aplica desconto | D6: UI / API | E6: CA03 | F6: 1. Acessar a Verzel Store com o carrinho vazio. 2. Adicionar 1 unidade de Mochila Urbana 20L. 3. Aplicar, um por vez: DESCONTO50, BEMVINDO, BEMVINDO100. 4. Conferir a mensagem, o desconto e o total em cada tentativa. 5. Repetir no canal API (Postman): POST /api/carrinho/calcular com os mesmos itens e cupom e conferir os mesmos valores. | G6: Mensagem do cupom: "Cupom inválido." Desconto: R$ 0,00 Total: R$ 119,90 | H6: Passou | K6: Yasmin Leite / 09-10-2030
A7: CT-06 | B7: Cupom | C7: Cupom expirado exibe "Cupom expirado." e não aplica desconto | D7: UI / API | E7: CA04, automatizar | F7: 1. Acessar a Verzel Store com o carrinho vazio. 2. Adicionar 1 unidade de Mochila Urbana 20L. 3. Aplicar, um por vez: VERAO2026, verao2026. 4. Conferir a mensagem, o desconto e o total em cada tentativa. 5. Repetir no canal API (Postman): POST /api/carrinho/calcular com os mesmos itens e cupom e conferir os mesmos valores. | G7: Mensagem do cupom: "Cupom expirado." Desconto: R$ 0,00 Total: R$ 119,90 | H7: Passou | K7: Yasmin Leite / 09-10-2031
A8: CT-07 | B8: Cupom | C8: Não é possível aplicar um segundo cupom sem remover o atual | D8: UI | E8: CA05, AMB-01 | F8: 1. Acessar a Verzel Store com o carrinho vazio. 2. Adicionar 1 unidade de Mochila Urbana 20L. 3. Aplicar o cupom BEMVINDO10. 4. Tentar aplicar o cupom VERAO2026 sem remover o atual. | G8: A interface não permite aplicar o segundo cupom. BEMVINDO10 continua aplicado. Desconto continua R$ 10,00. | H8: Passou | K8: Yasmin Leite / 09-10-2032 | L8: Sistema só permite adicinoar novo cupom após remover o atual.
A9: CT-08 | B9: Cupom | C9: Remover o cupom atual e aplicar outro | D9: UI | E9: CA05 | F9: 1. Acessar a Verzel Store com o carrinho vazio. 2. Adicionar 1 unidade de Mochila Urbana 20L. 3. Aplicar o cupom BEMVINDO10. 4. Remover o cupom atual e conferir desconto e total. 5. Aplicar o cupom VERAO2026. | G9: Após remover: desconto R$ 0,00 e total R$ 119,90. Após aplicar VERAO2026: mensagem "Cupom expirado." e desconto R$ 0,00. | H9: Passou | K9: Yasmin Leite / 09-10-2033
A10: CT-09 | B10: Cupom | C10: Um cupom inválido não impede aplicar um cupom válido em seguida | D10: UI | E10: CA03 | F10: 1. Acessar a Verzel Store com o carrinho vazio. 2. Adicionar 1 unidade de Mochila Urbana 20L. 3. Aplicar DESCONTO50 e confirmar a mensagem "Cupom inválido." 4. Aplicar BEMVINDO10. | G10: Desconto R$ 10,00 e total R$ 109,90. | H10: Passou | K10: Yasmin Leite / 09-10-2034
A11: CT-10 | B11: Cupom | C11: Desconto e frete são recalculados ao alterar o carrinho com cupom aplicado | D11: UI | E11: CA01, CA06, BUG | F11: 1. Acessar a Verzel Store com o carrinho vazio. 2. Adicionar 1 unidade de Mochila Urbana 20L. 3. Aplicar o cupom BEMVINDO10. 4. Aumentar a quantidade da Mochila para 2 e conferir o resumo. 5. Reduzir a quantidade da Mochila para 1 e conferir o resumo. | G11: Com 2 unidades: subtotal R$ 200,00; desconto R$ 20,00; frete R$ 0,00; total R$ 180,00. Com 1 unidade: desconto R$ 10,00; frete R$ 19,90; total R$ 109,90. | H11: Falhou | K11: Yasmin Leite / 09-10-2035 | L11: Marcado como BUG no arquivo .feature. README relaciona o BUG-003 a este caso.
A12: CT-11 | B12: Cupom | C12: Espaço no meio do código não é ignorado | D12: UI / API | E12: CA02, CA03, AMB-02 | F12: 1. Acessar a Verzel Store com o carrinho vazio. 2. Adicionar 1 unidade de Mochila Urbana 20L. 3. Aplicar o cupom 'BEM VINDO10' (com espaço no meio). 4. Conferir mensagem, desconto e total. 5. Repetir no canal API (Postman): POST /api/carrinho/calcular com os mesmos itens e cupom e conferir os mesmos valores. | G12: Mensagem do cupom: "Cupom inválido." Desconto: R$ 0,00 Total: R$ 119,90 | H12: Passou | K12: Yasmin Leite / 09-10-2036
A13: CT-12 | B13: Frete | C13: Abaixo de R$ 200,00 cobra frete fixo e informa quanto falta | D13: UI / API | E13: CA07 | F13: 1. Acessar a Verzel Store com o carrinho vazio. 2. Para cada carrinho abaixo, conferir subtotal, frete, valor faltante e total: (a) 1 Mochila Urbana 20L; (b) 1 Boné Aba Curva; (c) 5 Kit 3 Pares de Meias; (d) 1 Tênis Casual Urbano. 3. Repetir no canal API (Postman): POST /api/carrinho/calcular com os mesmos itens e cupom e conferir os mesmos valores. | G13: Frete: R$ 19,90 em todos os casos. (a) subtotal R$ 100,00; faltam R$ 100,00; total R$ 119,90 (b) subtotal R$ 49,90; faltam R$ 150,10; total R$ 69,80 (c) subtotal R$ 149,50; faltam R$ 50,50; total R$ 169,40 (d) subtotal R$ 189,90; faltam R$ 10,10; total R$ 209,80 | H13: Passou | K13: Yasmin Leite / 09-10-2037
A14: CT-13 | B14: Frete | C14: Subtotal exatamente igual a R$ 200,00 tem frete grátis (limite inclusivo) | D14: UI / API | E14: CA06, automatizar, BUG | F14: 1. Acessar a Verzel Store com o carrinho vazio. 2. Para cada carrinho, conferir subtotal, frete, aviso de valor faltante e total: (a) 2 Mochila Urbana 20L; (b) 1 Mochila Urbana 20L + 2 Garrafa Térmica 750ml; (c) 4 Garrafa Térmica 750ml. 3. Repetir no canal API (Postman): POST /api/carrinho/calcular com os mesmos itens e cupom e conferir os mesmos valores. | G14: Subtotal: R$ 200,00 Frete: R$ 0,00 Sem aviso de valor faltante Total: R$ 200,00 | H14: Falhou | I14: BUG-003 | K14: Yasmin Leite / 09-10-2038 | L14: Marcado como BUG no arquivo .feature. README relaciona o BUG-003 a este caso. (mesmo padrão do CT10).
A15: CT-14 | B15: Frete | C15: Logo abaixo do limite ainda cobra frete | D15: UI / API | E15: CA06, CA07 | F15: 1. Acessar a Verzel Store com o carrinho vazio. 2. Conferir os carrinhos: (a) 1 Camiseta Essencial + 1 Calça Jeans Slim; (b) 4 Boné Aba Curva. 3. Repetir no canal API (Postman): POST /api/carrinho/calcular com os mesmos itens e cupom e conferir os mesmos valores. | G15: Frete: R$ 19,90 nos dois casos. (a) subtotal R$ 199,80; faltam R$ 0,20; total R$ 219,70 (b) subtotal R$ 199,60; faltam R$ 0,40; total R$ 219,50 | H15: Passou | K15: Yasmin Leite / 09-10-2039
A16: CT-15 | B16: Frete | C16: Acima de R$ 200,00 o frete é grátis | D16: UI / API | E16: CA06 | F16: 1. Acessar a Verzel Store com o carrinho vazio. 2. Adicionar 1 unidade de Jaqueta Corta-Vento. 3. Conferir o resumo. 4. Repetir no canal API (Postman): POST /api/carrinho/calcular com os mesmos itens e cupom e conferir os mesmos valores. | G16: Subtotal: R$ 229,90 Frete: R$ 0,00 Total: R$ 229,90 | H16: Passou | J16: { "itens": [ { "produtoId": "P007", "nome": "Jaqueta Corta-Vento", "precoUnitario": 229.9, "quantidade": 1, "total": 229.9 } ], "subtotal": 229.9, "desconto": 0, "frete": 0, "freteGratis": true, "valorFaltanteFreteGratis": 0, "total": 229.9, "cupom": null } | K16: Yasmin Leite / 09-10-2040
A17: CT-16 | B17: Frete | C17: O frete grátis considera o subtotal antes do desconto do cupom | D17: UI / API | E17: CA08, automatizar | F17: 1. Acessar a Verzel Store com o carrinho vazio. 2. Adicionar 1 unidade de Tênis Casual Urbano e 1 unidade de Kit 3 Pares de Meias. 3. Aplicar o cupom BEMVINDO10. 4. Conferir o resumo. 5. Repetir no canal API (Postman): POST /api/carrinho/calcular com os mesmos itens e cupom e conferir os mesmos valores. | G17: Subtotal: R$ 219,80 Desconto: R$ 21,98 Frete: R$ 0,00 Total: R$ 197,82 (abaixo de R$ 200,00, mas o frete continua grátis) | H17: Passou | K17: Yasmin Leite / 09-10-2041
A18: CT-17 | B18: Frete | C18: Abaixo do limite com cupom, o valor faltante usa o subtotal antes do desconto | D18: UI / API | E18: CA07, CA08 | F18: 1. Acessar a Verzel Store com o carrinho vazio. 2. Adicionar 4 unidades de Boné Aba Curva. 3. Aplicar o cupom BEMVINDO10. 4. Conferir o resumo. 5. Repetir no canal API (Postman): POST /api/carrinho/calcular com os mesmos itens e cupom e conferir os mesmos valores. | G18: Subtotal: R$ 199,60 Desconto: R$ 19,96 Frete: R$ 19,90 Faltam R$ 0,40 para o frete grátis Total: R$ 199,54 | H18: Passou | J18: {"itens":[{"produtoId":"P004","quantidade":4}],"cupom":"BEMVINDO10"} { "itens": [ { "produtoId": "P004", "nome": "Boné Aba Curva", "precoUnitario": 49.9, "quantidade": 4, "total": 199.6 } ], "subtotal": 199.6, "desconto": 19.96, "frete": 19.9, "freteGratis": false, "valorFaltanteFreteGratis": 0.4, "total": 199.54, "cupom": { "codigo": "BEMVINDO10", "aplicado": true, "mensagem": "Cupom aplicado: 10% de desconto nos produtos." } } | K18: Yasmin Leite / 09-10-2042
A19: CT-18 | B19: Frete | C19: O aviso de frete muda ao ultrapassar o limite e volta ao reduzir o carrinho | D19: UI | E19: CA06, CA07 | F19: 1. Acessar a Verzel Store com o carrinho vazio. 2. Adicionar 1 unidade de Mochila Urbana 20L e confirmar o aviso "faltam R$ 100,00". 3. Adicionar mais 1 unidade de Mochila Urbana 20L e conferir frete e aviso. 4. Remover 1 unidade de Mochila Urbana 20L e conferir frete e aviso. | G19: Com 2 unidades: frete R$ 0,00 e sem aviso de valor faltante. Após remover 1: frete R$ 19,90 e aviso "faltam R$ 100,00". | H19: Passou | K19: Yasmin Leite / 09-10-2043 | L19: O valor exibido de R$200,00 deveria ser disppnibilizado frete gratuito, e o comportamento desde teste é apenas não exibir valor faltando, por isso é um teste válido, mas o outro comportamento acomapanha o BUG-003.
A20: CT-19 | B20: Carrinho | C20: Cinco unidades do mesmo produto são permitidas | D20: UI / API | E20: CA10 | F20: 1. Acessar a Verzel Store com o carrinho vazio. 2. Adicionar 5 unidades de Garrafa Térmica 750ml. 3. Conferir quantidade, subtotal e total. 4. API: POST /api/carrinho/calcular com P008 x5 e conferir os mesmos valores. | G20: Quantidade: 5 Subtotal: R$ 250,00 Total: R$ 250,00 | H20: Passou | K20: Yasmin Leite / 09-10-2044
A21: CT-20 | B21: Carrinho | C21: A sexta unidade do mesmo produto não é aceita na interface | D21: UI | E21: CA10, AMB-06 | F21: 1. Acessar a Verzel Store com o carrinho vazio. 2. Adicionar 5 unidades de Garrafa Térmica 750ml. 3. Tentar aumentar a quantidade da Garrafa Térmica 750ml. | G21: Quantidade continua 5. Subtotal continua R$ 250,00. | H21: Passou | K21: Yasmin Leite / 09-10-2045 | L21: AMB-06: registrar se há mensagem ou se o botão fica desabilitado.
A22: CT-21 | B22: Carrinho | C22: Adições repetidas pela lista de produtos respeitam o limite acumulado | D22: UI | E22: CA10, AMB-06 | F22: 1. Acessar a Verzel Store com o carrinho vazio. 2. Na lista de produtos, clicar 6 vezes em "Adicionar ao carrinho" do Boné Aba Curva. 3. Conferir a quantidade e o subtotal no carrinho. | G22: Quantidade de Boné Aba Curva no carrinho: 5 Subtotal: R$ 249,50 | H22: Passou | K22: Yasmin Leite / 09-10-2046
A23: CT-22 | B23: Carrinho | C23: O limite de 5 unidades vale por produto, não pelo carrinho todo | D23: UI | E23: CA10 | F23: 1. Acessar a Verzel Store com o carrinho vazio. 2. Adicionar 5 unidades de Garrafa Térmica 750ml. 3. Adicionar 5 unidades de Kit 3 Pares de Meias. 4. Conferir o carrinho. | G23: 5 unidades de Garrafa Térmica 750ml e 5 unidades de Kit 3 Pares de Meias. Subtotal: R$ 399,50 | H23: Passou | K23: Yasmin Leite / 09-10-2047
A24: CT-23 | B24: Carrinho | C24: Alterar a quantidade ou remover um item atualiza os valores | D24: UI | E24: - | F24: 1. Acessar a Verzel Store com o carrinho vazio. 2. Adicionar 2 unidades de Mochila Urbana 20L e 1 unidade de Boné Aba Curva. 3. Reduzir a quantidade da Mochila Urbana 20L para 1 e conferir o subtotal. 4. Remover o Boné Aba Curva e conferir subtotal e total. | G24: Após reduzir a Mochila: subtotal R$ 149,90. Após remover o Boné: subtotal R$ 100,00 e total R$ 119,90. | H24: Passou | K24: Yasmin Leite / 09-10-2048
A25: CT-24 | B25: Carrinho | C25: Valores têm 2 casas decimais, sem resíduos de ponto flutuante | D25: UI / API | E25: CA11 | F25: 1. Acessar a Verzel Store com o carrinho vazio. 2. Para Calça Jeans Slim e depois Kit 3 Pares de Meias: adicionar 3 unidades e conferir subtotal e total sem cupom. 3. Aplicar BEMVINDO10 e conferir subtotal, desconto e total. 4. API: repetir com POST /api/carrinho/calcular (P002 x3 e P006 x3) e verificar que nenhum valor monetário da resposta tem mais de 2 casas decimais. | G25: Calça Jeans Slim x3: sem cupom subtotal R$ 419,70 e total R$ 419,70; com cupom desconto R$ 41,97 e total R$ 377,73. Kit 3 Pares de Meias x3: sem cupom subtotal R$ 89,70 e total R$ 109,60; com cupom desconto R$ 8,97 e total R$ 100,63. | H25: Passou | K25: Yasmin Leite / 09-10-2049 | L25: Em ponto flutuante: 139.9*3 = 419.70000000000005 e 29.9*3 = 89.69999999999999.
A26: CT-25 | B26: Carrinho | C26: O contador do menu "Carrinho" reflete o conteúdo do carrinho | D26: UI | E26: AMB-16 | F26: 1. Acessar a Verzel Store com o carrinho vazio. 2. Confirmar que o contador do menu "Carrinho" mostra 0. 3. Adicionar 2 unidades de Boné Aba Curva e 1 unidade de Camiseta Essencial. 4. Conferir o contador. | G26: Contador mostra 3 (soma de unidades). | H26: Passou | K26: Yasmin Leite / 09-10-2050 | L26: AMB-16: registrar se mostra 2 (produtos distintos).
A27: CT-26 | B27: Carrinho | C27: O carrinho persiste ao recarregar a mesma aba e começa vazio em outra aba | D27: UI | E27: AMB-15 | F27: 1. Acessar a Verzel Store com o carrinho vazio. 2. Adicionar 1 unidade de Camiseta Essencial. 3. Recarregar a página e conferir o carrinho. 4. Abrir a loja em outra aba do navegador e conferir o carrinho. | G27: Após recarregar: carrinho continua com 1 unidade de Camiseta Essencial. Em outra aba: carrinho vazio. | H27: Passou | K27: Yasmin Leite / 09-10-2051
A28: CT-27 | B28: Carrinho | C28: O catálogo exibe os 8 produtos com nome e preço corretos | D28: UI / API | E28: - | F28: 1. Acessar a página de produtos. 2. Contar os produtos exibidos. 3. API: GET /api/produtos e comparar nome e preço de cada produto com a interface. | G28: 8 produtos exibidos. Nome e preço iguais aos do endpoint GET /api/produtos. Preços no formato "R$ 59,90". | H28: Passou | K28: Yasmin Leite / 09-10-2052
A29: CT-28 | B29: Pedido | C29: Confirmar um pedido válido sem cupom | D29: UI | E29: smoke | F29: 1. Acessar a Verzel Store com o carrinho vazio. 2. Adicionar 1 unidade de Mochila Urbana 20L. 3. Finalizar o pedido com nome Maria Silva, e-mail maria@exemplo.com e CEP 01310-100. 4. Conferir a confirmação do pedido. | G29: Confirmação com número no formato VZ- seguido de 6 dígitos. Resumo: subtotal R$ 100,00; frete R$ 19,90; total R$ 119,90. | H29: Passou | K29: Yasmin Leite / 09-10-2053
A30: CT-29 | B30: Pedido | C30: Criar pedido via API com cupom devolve o mesmo resumo do cálculo | D30: API | E30: CA01, CA09, automatizar | F30: 1. Postman: POST /api/pedidos com o corpo: { "cliente": { "nome": "Maria Silva", "email": "maria@exemplo.com", "cep": "01310-100" }, "itens": [ { "produtoId": "P005", "quantidade": 1 } ], "cupom": "BEMVINDO10" } 2. Conferir status e campos da resposta. | G30: Status 201. numero no formato ^VZ-[0-9]{6}$ criadoEm em ISO 8601 cliente.cep = "01310100" subtotal 100 e desconto 10 frete 19.9 e freteGratis false valorFaltanteFreteGratis 100 total 109.9 cupom.aplicado true | H30: Passou | K30: Yasmin Leite / 09-10-2054
A31: CT-30 | B31: Pedido | C31: Nome sem sobrenome é rejeitado | D31: UI / API | E31: AMB-10, BUG | F31: 1. Acessar a Verzel Store com o carrinho vazio. 2. Adicionar 1 unidade de Mochila Urbana 20L. 3. Finalizar o pedido com e-mail maria@exemplo.com, CEP 01310-100 e, um por vez, os nomes: 'Maria' (espaço no final), vazio. 4. Conferir a resposta em cada tentativa. 5. API: repetir com POST /api/pedidos. | G31: Pedido rejeitado com erro de validação no campo "nome" nas três tentativas. | H31: Passou | K31: Yasmin Leite / 09-10-2055
A32: CT-31 | B32: Pedido | C32: Validação do formato do e-mail | D32: UI / API | E32: AMB-11 | F32: 1. Acessar a Verzel Store com o carrinho vazio. 2. Adicionar 1 unidade de Mochila Urbana 20L. 3. Finalizar com nome Maria Silva, CEP 01310-100 e o e-mail maria@exemplo.com. 4. Repetir, um por vez, com: maria.exemplo.com, maria@, @exemplo.com, maria@exemplo. 5. API: repetir com POST /api/pedidos. | G32: maria@exemplo.com: pedido confirmado. Os quatro e-mails inválidos: pedido rejeitado com erro de validação no campo "email". | H32: Falhou | K32: Yasmin Leite / 09-10-2056 | L32: O sistema aceita qualquee validação desde que no formato tenha "@" e "."
A33: CT-32 | B33: Pedido | C33: Validação do CEP (8 dígitos, com ou sem hífen) | D33: UI / API | E33: AMB-12 | F33: 1. Acessar a Verzel Store com o carrinho vazio. 2. Adicionar 1 unidade de Mochila Urbana 20L. 3. Finalizar com nome Maria Silva, e-mail maria@exemplo.com e CEP 01310-100; repetir com 01310100. 4. Repetir, um por vez, com: 0131010, 013101000, 0131010A, 013101-00. 5. API: repetir com POST /api/pedidos. | G33: 01310-100 e 01310100: pedido confirmado. Os quatro CEPs inválidos: pedido rejeitado com erro de validação no campo "cep". | H33: Passou | K33: Yasmin Leite / 09-10-2057
A34: CT-33 | B34: Pedido | C34: Não é possível finalizar um pedido com o carrinho vazio | D34: UI / API | E34: AMB-14 | F34: 1. Acessar a Verzel Store com o carrinho vazio. 2. Tentar finalizar o pedido com o carrinho vazio. 3. API: POST /api/pedidos com cliente válido e "itens": []. | G34: UI: finalização não é permitida. API: status 422 e erro.codigo ITENS_OBRIGATORIOS. | H34: Passou | K34: Yasmin Leite / 09-10-2060
A35: CT-34 | B35: Pedido | C35: UI e API exibem os mesmos valores para o mesmo carrinho | D35: UI / API | E35: smoke | F35: 1. Acessar a Verzel Store com o carrinho vazio. 2. Montar na interface cada carrinho: (a) 1 Mochila Urbana 20L com BEMVINDO10; (b) 4 Boné Aba Curva sem cupom; (c) 1 Jaqueta Corta-Vento com BEMVINDO10. 3. Para cada um, enviar POST /api/carrinho/calcular com os mesmos itens e cupom. 4. Comparar subtotal, desconto, frete, valor faltante e total. | G35: Todos os valores da API são iguais aos exibidos no carrinho, nos três casos. | H35: Passou | K35: Yasmin Leite / 09-10-2061
A36: CT-35 | B36: Pedido | C36: O fluxo não tem etapa de pagamento online | D36: UI | E36: - | F36: 1. Acessar a Verzel Store com o carrinho vazio. 2. Adicionar 1 unidade de Mochila Urbana 20L. 3. Finalizar o pedido com dados válidos. | G36: Nenhum dado de pagamento é solicitado. A confirmação do pedido é exibida. | H36: Passou | K36: Yasmin Leite / 09-10-2062
A37: CT-36 | B37: Contrato da API | C37: Listar produtos | D37: API | E37: smoke | F37: 1. Postman: GET /api/produtos. 2. Conferir status, quantidade, campos e preços. | G37: Status 200 e lista com 8 produtos. Cada produto com id, nome, descricao, categoria e preco. Preços de P001 a P008: 59.9, 139.9, 189.9, 49.9, 100, 29.9, 229.9 e 50. | H37: Passou | K37: Yasmin Leite / 09-10-2063
A38: CT-37 | B38: Contrato da API | C38: Consultar produto existente | D38: API | E38: - | F38: 1. Postman: GET /api/produtos/P001. | G38: Status 200; nome "Camiseta Essencial" e preco 59.9. | H38: Passou | K38: Yasmin Leite / 09-10-2064
A39: CT-38 | B39: Contrato da API | C39: Consultar produto inexistente | D39: API | E39: AMB-19 | F39: 1. Postman: GET /api/produtos/P999. 2. Repetir com /api/produtos/P000. | G39: Nos dois casos: status 404 e erro.codigo PRODUTO_NAO_ENCONTRADO. | H39: Passou | K39: Yasmin Leite / 09-10-2065 | L39: Variante a registrar sem classificar como bug: GET /api/produtos/p001 (minúsculo).
A40: CT-39 | B40: Contrato da API | C40: Cálculo com cupom inválido ou expirado não gera erro | D40: API | E40: CA03, CA04 | F40: 1. Postman: POST /api/carrinho/calcular com 1 unidade de P005 e cupom DESCONTO50. 2. Repetir com o cupom VERAO2026. | G40: Status 200; desconto 0; total 119.9; cupom.aplicado false. DESCONTO50: cupom.mensagem "Cupom inválido." VERAO2026: cupom.mensagem "Cupom expirado." | H40: Passou | K40: Yasmin Leite / 09-10-2066
...
